Workbook

Sheet Assumptions
A1: CARRY ANALYSIS – ASSUMPTIONS
A2: ▶ TRADE SELECTION
A3: Selected Pool | B3: FR SL4960 | C3: FICO story pool – FR; chosen on RV
A4: Ticker | B4: FR SL4960 | C4: Bloomberg: FR SL4960 Mtge
A5: Coupon (%) | B5: 6 | C5: Source: Bloomberg DES 6/22/2026
A6: Pool Price (clean, 32nds-decimal) | B6: 102.875 | C6: 102-28 = 102 + 28/32
A7: Pay-Up over TBA (ticks, 1/32nds) | B7: 29.5 | C7: +29+ means 29 and 1/2 tick = 29.5/32nds; Source: desk
A9: ▶ TBA ROLL (OBSERVED – FNCL 6 7/26)
A10: Jul-Aug Drop (ticks 1/32nd) | B10: 3.936 | C10: Observed spec drop at 102-23 (TBA+payup), 17.3 CPR, 3.7% IFR, 7/13→8/13; Source: Bloomberg RA 6/22/2026
A11: Aug-Sep Drop (ticks 1/32nd) | B11: 4.132 | C11: Observed spec drop at 102-23 (TBA+payup), 17.3 CPR, 3.7% IFR, 8/13→9/14; Source: Bloomberg RA 6/22/2026
A12: Sep-Oct Drop – assumption | B12: See by-CPR table below | C12: Projected; interpolated from 8 → 5.75 trend; update when available
A14: ▶ IMPLIED FINANCING RATE (B/E FIN RATE)
A15: Jul-Aug IFR (%) | B15: 3.7 | C15: Source: Bloomberg RA screen 6/22/2026
A16: Aug-Sep IFR (%) | B16: 3.7 | C16: Same as Jul-Aug; desk guidance
A17: Sep-Oct IFR (%) | B17: 3.95 | C17: Priced-in Fed hike; desk guidance
A19: ▶ PREPAYMENT SCENARIOS (CPR)
A20: CPR Min (%) | B20: 5 | C20: Lower bound of scenario range
A21: CPR Max (%) | B21: 25 | C21: Upper bound of scenario range
A22: CPR Step | B22: 5 | C22: Increment
A23: Base-Case CPR (%) | B23: 17.3 | C23: FR SL4960 1M CPR Jun-26; Source: Bloomberg DES
A25: ▶ POOL CHARACTERISTICS (FR SL4960)
A26: WAC (%) | B26: 6.974 | C26: Source: Bloomberg DES 6/22/2026
A27: WAM (months) | B27: 325 | C27: Source: Bloomberg DES
A28: WALA (months) | B28: 30 | C28: Source: Bloomberg DES
A29: Avg FICO | B29: 676 | C29: Source: Bloomberg DES; CL FICO story
A30: Avg LTV | B30: 80 | C30: Source: Bloomberg DES
A31: # Loans | B31: 2841 | C31: Source: Bloomberg DES
A32: Balance ($mm) | B32: 110.28 | C32: Current UPB; Source: Bloomberg DES
A33: Vintage | B33: FNCL 6 2023 | C33: Source: Bloomberg DES
A35: Jul-Aug POOL CARRY by CPR (RA, imm=102-23, IFR=3.7%) | B35: Drop (ticks) | C35: Source: Bloomberg RA FNCL 6 7/26, 7/13→8/13, 6/22/2026
A36: 5% CPR | B36: 5.009
A37: 10% CPR | B37: 4.592
A38: 15% CPR | B38: 4.15
A39: 17% CPR | B39: 3.965
A40: 20% CPR | B40: 3.679
A41: 25% CPR | B41: 3.175
A42: Aug-Sep POOL CARRY by CPR (RA, imm=102-23, IFR=3.7%) | B42: Drop (ticks) | C42: Source: Bloomberg RA FNCL 6 7/26, 8/13→9/14, 6/22/2026
A43: 5% CPR | B43: 5.204
A44: 10% CPR | B44: 4.788
A45: 15% CPR | B45: 4.246
...

Sheet TBA Roll Table
A1: TBA ROLL CARRY TABLE (in ticks, 1/32nd per $1mm face)
A2: TBA Roll Cost = negative of the generic TBA drop (RA at TBA price, no pay-up). Jul-Aug: −8.000 ticks. Aug-Sep: −5.750 ticks (CPR-invariant for near months). Sep-Oct: CPR-specific drops from Bloomberg RA at generic price (run separately).
A3: Mechanics: Rolling a TBA short = sell near, buy far. You receive the drop when you roll from near to far. For SPECIAL pools the TBA trades rich, so the special drop is HIGHER than the generic roll – this is a COST to the spec pool long position. Net TBA roll carry = −Drop (the short TBA roll is a negative carry item).
A4: CPR Scenario | B4: Jul-Aug | C4: Aug-Sep | D4: Sep-Oct
A5: 5% CPR | B5: =-Assumptions!$B$57 -> -8 | C5: =-Assumptions!$B$58 -> -5.75 | D5: =-Assumptions!$B$61 -> -4.483
A6: 10% CPR | B6: =-Assumptions!$B$57 -> -8 | C6: =-Assumptions!$B$58 -> -5.75 | D6: =-Assumptions!$B$62 -> -4.065
A7: 15% CPR | B7: =-Assumptions!$B$57 -> -8 | C7: =-Assumptions!$B$58 -> -5.75 | D7: =-Assumptions!$B$63 -> -4.145
A8: 17% CPR | B8: =-Assumptions!$B$57 -> -8 | C8: =-Assumptions!$B$58 -> -5.75 | D8: =-Assumptions!$B$64 -> -4.018
A9: 20% CPR | B9: =-Assumptions!$B$57 -> -8 | C9: =-Assumptions!$B$58 -> -5.75 | D9: =-Assumptions!$B$65 -> -3.823
A10: 25% CPR | B10: =-Assumptions!$B$57 -> -8 | C10: =-Assumptions!$B$58 -> -5.75 | D10: =-Assumptions!$B$66 -> -3.478
A11: ◀ BASE CASE (17% CPR ≈ 1M CPR of FR SL4960)

Sheet Pool Carry Table
A1: POOL CARRY TABLE (in ticks, 1/32nd per $1mm face)
A2: Pool Carry = Bloomberg RA forward drop computed at adjusted imm. price (TBA price + 29.5 tick pay-up = 102-23). The pay-up is already embedded in the price input, so these drops are the spec-adjusted carry directly from RA. No further pay-up adjustment needed.
A3: Formula: Pool Carry (ticks) = TBA Drop (ticks) − [ Pay-Up (ticks) × IFR% / 12 ] where IFR is the B/E financing rate for that month from Bloomberg RA. Sep-Oct: Pool Carry is SET EQUAL to Pool Carry (assumption per desk) because Sep-Oct TBA drop is not yet tradeable; it equals the carry earned.
A4: CPR Scenario | B4: Jul-Aug | C4: Aug-Sep | D4: Sep-Oct
A5: 5% CPR | B5: =Assumptions!$B$10 -> 3.936 | C5: =Assumptions!$B$11 -> 4.132 | D5: =Assumptions!$B$50 -> 4.732
A6: 10% CPR | B6: =Assumptions!$B$10 -> 3.936 | C6: =Assumptions!$B$11 -> 4.132 | D6: =Assumptions!$B$51 -> 4.447
A7: 15% CPR | B7: =Assumptions!$B$10 -> 3.936 | C7: =Assumptions!$B$11 -> 4.132 | D7: =Assumptions!$B$52 -> 4.145
A8: 17% CPR | B8: =Assumptions!$B$10 -> 3.936 | C8: =Assumptions!$B$11 -> 4.132 | D8: =Assumptions!$B$53 -> 4.018
A9: 20% CPR | B9: =Assumptions!$B$10 -> 3.936 | C9: =Assumptions!$B$11 -> 4.132 | D9: =Assumptions!$B$54 -> 3.823
A10: 25% CPR | B10: =Assumptions!$B$10 -> 3.936 | C10: =Assumptions!$B$11 -> 4.132 | D10: =Assumptions!$B$55 -> 3.478
A11: ◀ BASE CASE (17% CPR ≈ 1M CPR of FR SL4960)

Sheet Net Carry Summary
A1: NET CARRY SUMMARY (ticks, 1/32nd) – Spec Pool Long vs TBA Short Hedge
A2: Position: LONG FR SL4960 spec pool + SHORT FNCL 6 TBA (hedge). The TBA roll is a COST (negative) because special pools command a higher drop. The Pool earns carry from its coupon relative to its financing cost (the drop). Net Carry = Pool Carry – TBA Roll Cost. Positive = carry-positive position.
A3: Component | B3: Jul-Aug | C3: Aug-Sep | D3: Sep-Oct | E3: 3-Month Total
A4: BASE CASE (17% CPR ≈ FR SL4960 1M CPR)
A5: Pool Carry (ticks) | B5: ='Pool Carry Table'!$B$8 -> 3.936 | C5: ='Pool Carry Table'!$C$8 -> 4.132 | D5: ='Pool Carry Table'!$D$8 -> 4.018 | E5: =SUM(B5,C5,D5) -> 12.086
A6: TBA Roll Cost (ticks, negative) | B6: ='TBA Roll Table'!$B$8 -> -8 | C6: ='TBA Roll Table'!$C$8 -> -5.75 | D6: ='TBA Roll Table'!$D$8 -> -4.018 | E6: =SUM(B6,C6,D6) -> -17.768
A7: NET CARRY (Pool − TBA Roll Cost) | B7: =B5+B6 -> -4.064 | C7: =C5+C6 -> -1.618 | D7: =D5+D6 -> 0 | E7: =SUM(B7,C7,D7) -> -5.682
A9: CPR SENSITIVITY – NET CARRY (ticks)
A10: CPR Scenario | B10: Jul-Aug | C10: Aug-Sep | D10: Sep-Oct | E10: 3-Month Total
A11: 5% CPR | B11: ='Pool Carry Table'!B5+'TBA Roll Table'!B5 -> -4.064 | C11: ='Pool Carry Table'!C5+'TBA Roll Table'!C5 -> -1.618 | D11: ='Pool Carry Table'!D5+'TBA Roll Table'!D5 -> 0.249 | E11: =SUM(B11,C11,D11) -> -5.433
A12: 10% CPR | B12: ='Pool Carry Table'!B6+'TBA Roll Table'!B6 -> -4.064 | C12: ='Pool Carry Table'!C6+'TBA Roll Table'!C6 -> -1.618 | D12: ='Pool Carry Table'!D6+'TBA Roll Table'!D6 -> 0.382 | E12: =SUM(B12,C12,D12) -> -5.3
A13: 15% CPR | B13: ='Pool Carry Table'!B7+'TBA Roll Table'!B7 -> -4.064 | C13: ='Pool Carry Table'!C7+'TBA Roll Table'!C7 -> -1.618 | D13: ='Pool Carry Table'!D7+'TBA Roll Table'!D7 -> 0 | E13: =SUM(B13,C13,D13) -> -5.682
A14: 17% CPR | B14: ='Pool Carry Table'!B8+'TBA Roll Table'!B8 -> -4.064 | C14: ='Pool Carry Table'!C8+'TBA Roll Table'!C8 -> -1.618 | D14: ='Pool Carry Table'!D8+'TBA Roll Table'!D8 -> 0 | E14: =SUM(B14,C14,D14) -> -5.682
A15: 20% CPR | B15: ='Pool Carry Table'!B9+'TBA Roll Table'!B9 -> -4.064 | C15: ='Pool Carry Table'!C9+'TBA Roll Table'!C9 -> -1.618 | D15: ='Pool Carry Table'!D9+'TBA Roll Table'!D9 -> 0 | E15: =SUM(B15,C15,D15) -> -5.682
A16: 25% CPR | B16: ='Pool Carry Table'!B10+'TBA Roll Table'!B10 -> -4.064 | C16: ='Pool Carry Table'!C10+'TBA Roll Table'!C10 -> -1.618 | D16: ='Pool Carry Table'!D10+'TBA Roll Table'!D10 -> 0 | E16: =SUM(B16,C16,D16) -> -5.682

Sheet Hedge Rationale
A1: HEDGE ANALYSIS – FR SL4960 Long Position
A2: Hedge | B2: Instrument | C2: Direction | D2: Ratio | E2: Hedges | F2: Notes / Risks
A3: 1. Basis Trade (Rate Duration) | B3: Short 10Y UST | C3: Short | D3: DV01-Neutral (32% ratio) | E3: Rate duration / parallel shift risk | F3: Risks: Curve twist (10Y vs MBS duration mismatch), spread widening independent of rates, convexity – pool has negative convexity at par, UST does not
A4: 2. Coupon Stack (MBS Basis / Spread) | B4: Short FNCL 5.5 TBA | C4: Short | D4: DV01-Neutral (73% ratio) | E4: MBS basis / OAS widening vs current coupon | F4: Risks: Roll specialness of 5.5 TBA diverges from 6.0, coupon drift as rates move, basis can widen for non-rate reasons (Fed taper, bank demand)
A5: 3. TBA Roll (Prepay / Carry) | B5: Short 7-26 FHLMC 6 TBA Long 8-26 FHLMC 6 TBA | C5: Short near / Long far | D5: 1:1 (dollar) | E5: Isolates spec pool pay-up vs TBA roll; hedges generic prepay exposure | F5: CORRECTED: Pool is special → TBA roll hedge has NEGATIVE carry. Rolling costs the special drop each month. Risks: specialness collapses (pay-up compresses), pool prepays faster than TBA (destroys pay-up value), financing rate spike widens carry gap
A6: ⚠ CORRECTION NOTE: The TBA roll hedge was listed with positive carry. This is incorrect for SPECIAL pools. Because FR SL4960 is a FICO story spec pool trading at +29 pay-up, the TBA into which you roll the hedge trades at a SPECIAL (rich) level. Rolling the short TBA costs you the special drop each month – this is NEGATIVE carry to the position. The Net Carry Summary sheet shows the corrected calculation.
