Workbook

Sheet Carry Summary
A1: FR SL4960 — 3-Month Carry Analysis (ticks, 1/32nd)
A2: CPR Assumption | B2: 17% CPR | C2: 15% CPR | D2: 10% CPR | E2: 3M Total
B3: Jul-Aug | C3: Aug-Sep | D3: Sep-Oct | E3: 3M Total
A4: TBA Roll (Short FNCL 6 TBA Hedge)
A5: Generic TBA Drop | B5: -8 | C5: -5.75 | D5: -4.447 | E5: -18.197
A6: Pool Carry (Long FR SL4960 Spec Pool)
A7: Spec-Adjusted Drop | B7: 3.936 | C7: 4.246 | D7: 4.064 | E7: 12.246
A8: Net Carry | B8: -4.064 | C8: -1.504 | D8: -0.383 | E8: -5.951
A10: Source: Bloomberg RA, FNCL 6 7/26 Mtge, 6/22/2026. Pool carry = RA drop at imm. price 102-23 (TBA + 29.5 tick pay-up). CPR assumptions: Jul-Aug 17% (1M speed), Aug-Sep 15% (seasonal slowdown), Sep-Oct 10% (Fed hike).
A12: TBA Roll Hedge — Analysis & Risks
A13: Trade Rationale
A14: The TBA roll hedge (short Jul-26 FNCL 6 TBA / long Aug-26 FNCL 6 TBA) isolates the spec pool pay-up as the primary source of return. By hedging with the same coupon TBA, duration risk, spread risk, and most prepay risk are neutralized, leaving the position exposed only to changes in the pay-up of FR SL4960 relative to generic FNCL 6 TBA collateral. This is the most precise hedge for a pay-up convergence or stability trade. The position is long the pool's FICO/LTV collateral story and short generic collateral through the TBA, making it a clean expression of spec pool value.
A15: Why Carry is Negative
A16: Because FR SL4960 is a special pool trading at +29.5 ticks pay-up, the TBA into which you roll the hedge trades at a special (rich) level. Rolling the short TBA costs the special drop each month — 8 ticks in Jul-Aug, 5.75 ticks in Aug-Sep. The spec-adjusted pool carry is lower than the generic drop because your cost basis is higher. The result is a carry-negative position of approximately −$93k over 3 months at base case. This is the price of admission for holding quality collateral — the trade thesis must be justified by pay-up stability or widening rather than carry income.
A17: Macro Tailwinds
A18: Fed rate hike in September: a hike keeps mortgage rates elevated, suppressing refinancing activity and new origination. This directly supports the pay-up by keeping spec pool supply constrained — fewer new FICO/LTV story pools come to market when origination is low, maintaining the scarcity premium embedded in SL4960's +29.5 tick pay-up. Additionally, limited supply of Fannie 6s specifically means existing spec pools like SL4960 face less competition from new issuance, keeping investor demand concentrated on a thin float. Continued hedge fund buying in the 6% spec stack provides a technical bid that could push the pay-up toward the +36 tick breakeven.
A19: Macro Risks
A20: Rates rally: if the Fed pivots or signals cuts, mortgage rates decline and refinancing picks up, eroding the prepay protection value embedded in the pay-up. Faster prepays destroy the pay-up by shortening the pool's life and reducing the duration advantage over generic TBA. Supply increase: if origination volumes rise, new FICO/LTV spec pools come to market and dilute the scarcity premium, compressing pay-ups across the 6% stack. Hedge fund unwind: concentrated positioning in 6% specs can reverse quickly — a single large fund reducing exposure can gap the pay-up down 5-10 ticks in an illiquid market, turning a stable carry trade into a mark-to-market loss well in excess of the carry cost. Roll specialness compression: if the TBA roll richness normalizes, the cost of carrying the hedge decreases, improving the net carry profile.
A22: Why the TBA Roll May Decrease Over the 3-Month Horizon
A23: What Drives Roll Richness
... A32: If the roll compresses as expected — from 8 ticks in Jul-Aug toward 4-5 ticks by Sep-Oct — the cost of carrying the TBA roll hedge decreases month over month. This is exactly what the carry table shows: the net carry improves from -4.064 ticks in Jul-Aug to -1.504 ticks in Aug-Sep to -0.383 ticks in Sep-Oct. The front month is the most expensive period to carry the hedge, and the position becomes progressively cheaper to hold as the roll normalizes into the fall. This means the negative carry is front-loaded — if the position is held through the full 3 months, the per-month drag decreases materially as roll richness fades with the Fed hike and seasonal factors.

Sheet Pool Selection
A1: Pool Selection — FR SL4960 vs FN FA4286
A2: Side-by-Side Characteristics
A3: Characteristic | B3: FN FA4286 | C3: FR SL4960 | D3: Advantage
A4: Price | B4: 103-11 | C4: 102-28 | D4: SL4960 — cheaper entry
A5: Yield (%) | B5: 5.049 | C5: 5.226 | D5: SL4960 — +17.7 bps yield pickup
A6: Vintage | B6: 2024 | C6: 2023 | D6: FA4286 — newer collateral
A7: Avg FICO | B7: 750 | C7: 676 | D7: FA4286 — higher credit quality
A8: Avg LTV | B8: 75 | C8: 80 | D8: FA4286 — lower LTV
A9: Max Loan Size | B9: $225k | C9: $1.14mm | D9: SL4960 — jumbo loans, slower prepay
A10: # Loans | B10: 500 | C10: 2,841 | D10: SL4960 — more diversified
A11: 1M CPR (%) | B11: 11.9 | C11: 17.3 | D11: FA4286 — slower current speed
A12: 3M CPR (%) | B12: 14.1 | C12: 19.4 | D12: FA4286 — slower 3M speed
A13: WAC (%) | B13: 6.939 | C13: 6.974 | D13: SL4960 — marginally higher WAC
A14: Balance ($mm) | B14: 84.5 | C14: 110.3 | D14: SL4960 — larger, more liquid
... A17: Pay-Up (ticks) | B17: Higher | C17: +29.5 | D17: SL4960 — lower pay-up, better value
A19: Key Decision Factors — Why FR SL4960
A20: 1. Loan Size is the Dominant Prepay Driver in a Hiking Cycle
A21: FR SL4960's average loan size of $1.14mm (jumbo) versus FA4286's $225k (conforming) is the single most important differentiator in the current rate environment. Jumbo borrowers locked in large mortgages at favorable rates and face enormous payment shock if they refinance at today's rates. The cost of refinancing a $1mm+ loan at a rate 200+ bps higher is prohibitive, creating structural prepay protection that is durable across multiple rate scenarios. This is not the case for conforming borrowers — a $225k loan has a much lower absolute payment increase and a lower breakeven for refinancing to make economic sense.
A22: 2. Fed Rate Hike Pricing Amplifies the Loan Size Advantage
A23: With a Fed rate hike priced in for September and rates expected to remain elevated, the refinancing incentive for jumbo borrowers deteriorates further. Each hike increases the payment differential between the current mortgage and a new loan, making prepayment less rational for SL4960's borrower base. FA4286's conforming borrowers are more sensitive to any rate relief — even a partial rally that does not bring rates back to prior lows could trigger a wave of conforming refinancing while leaving jumbo borrowers locked in place. This asymmetry makes SL4960 the better slow-pay story specifically because of the macro environment.
A24: 3. Yield Pickup and Lower Pay-Up Offer Better Risk-Adjusted Entry
A25: SL4960 offers a 17.7 bps yield advantage over FA4286 (5.226% vs 5.049%) at a lower price (102-28 vs 103-11) and a lower pay-up. FA4286's higher FICO (750) and lower LTV (75) command a premium that is already fully priced in — investors have bid up high-FICO collateral aggressively and the marginal value of an additional FICO point is diminishing. SL4960's 676 FICO / 80 LTV profile is less glamorous but the prepay story is driven by loan size, not credit quality, making the current pay-up of +29.5 ticks better value than FA4286's equivalent.
A26: 4. Diversification and Liquidity
A27: SL4960's 2,841 loans versus FA4286's 500 loans provides significantly better diversification — no single borrower prepaying has a meaningful impact on the pool factor. The larger balance ($110.3mm vs $84.5mm) also provides better liquidity when unwinding the position.
A29: Who Buys FR SL4960 on Unwind?
A30: Primary Buyers
A31: The most natural buyers of FR SL4960 on unwind are other hedge funds and relative value MBS investors who run similar spec pool strategies. These buyers are actively looking for current coupon FICO/loan size story pools and will recognize SL4960's collateral profile as a clean, well-understood trade. Given the current elevated hedge fund activity in the 6% spec stack, there is a reasonable active buyer base for this pool at or near the current pay-up. Money managers and insurance companies running MBS mandates are secondary buyers — they tend to be more buy-and-hold but will step in for quality collateral at attractive spreads.
... A33: The primary unwind risk is that the buyer base is concentrated among hedge funds who may all be reducing exposure simultaneously — particularly if there is a broader risk-off event or a rates rally that causes spec pool strategies to underperform. In that scenario, you may need to sell at a compressed pay-up to attract a real-money buyer (insurance, money manager) who will demand a concession for taking on the illiquidity. At $50mm notional the position is manageable — it is not so large that it moves the market, but it is large enough that a motivated seller would need to work the trade over 1-2 days to avoid pushing the pay-up down. The 2,841-loan diversification and $110mm balance make this more attractive to institutional buyers than a smaller, more concentrated pool would be.

Sheet P&L
A1: FR SL4960 — P&L Analysis
B2: Jul-Aug | C2: Aug-Sep | D2: Sep-Oct | E2: 3M Total
A3: Position Inputs
A4: Notional ($mm face) | B4: 50
A5: Tick Value ($/tick/$1mm face) | B5: 312.5
A6: Pool Price (incl. pay-up, 32nds decimal) | B6: 102.875
A7: Pay-Up (ticks, 1/32nd) | B7: 29.5
A8: Implied Financing Rate — Jul/Aug | B8: 0.037
A9: Implied Financing Rate — Sep/Oct | B9: 0.0395
A10: Net Carry (ticks, 1/32nd) — Pool Carry minus TBA Roll Cost
A11: TBA Roll Cost (ticks) | B11: -8 | C11: -5.75 | D11: -4.447 | E11: -18.197
A12: Pool Carry / Spec-Adjusted Drop (ticks) | B12: 3.936 | C12: 4.246 | D12: 4.064 | E12: 12.246
A13: Net Carry (ticks) | B13: -4.064 | C13: -1.504 | D13: -0.383 | E13: -5.951
A14: Dollar P&L
A15: P&L per $1mm face ($/month) | B15: -1270 | C15: -470 | D15: -119.6875 | E15: -1859.6875
A16: P&L on $50mm Notional ($) | B16: -63500 | C16: -23500 | D16: -5984.375 | E16: -92984.375
A17: Pay-Up Cost (upfront capital at risk)
A18: Pay-Up Cost ($) = 29.5/32 × $50mm | B18: 460937.5
A19: Pay-Up as % of Notional | B19: 0.00921875
A20: Summary
A21: Total 3M Net Carry P&L | E21: -92984.375
A22: Upfront Pay-Up Cost | E22: -460937.5
A23: Net Position P&L (Carry + Pay-Up if unwound at same pay-up) | E23: -553921.88
A25: Tick value = $312.50 per tick per $1mm face (1/32nd of 1% of $1mm). Net carry = spec-adjusted pool drop minus generic TBA roll cost. CPR assumptions: Jul-Aug 17%, Aug-Sep 15%, Sep-Oct 10%. Pay-up cost assumes position unwound at same +29.5 tick pay-up; if pay-up compresses, additional loss is incurred. Source: Bloomberg RA, FNCL 6 7/26 Mtge, 6/22/2026.
A27: Pay-Up Sensitivity — P&L at Different Exit Pay-Ups
A28: Exit Pay-Up (ticks) | B28: Δ Pay-Up (ticks) | C28: Pay-Up P&L ($) | D28: 3M Carry P&L ($) | E28: Total P&L ($) | F28: Breakeven?
A29: 0 | B29: -29.5 | C29: -460937.5 | D29: -92984.375 | E29: -553921.88
A30: 10 | B30: -19.5 | C30: -304687.5 | D30: -92984.375 | E30: -397671.88
A31: 15 | B31: -14.5 | C31: -226562.5 | D31: -92984.375 | E31: -319546.88
A32: 20 | B32: -9.5 | C32: -148437.5 | D32: -92984.375 | E32: -241421.88
A33: 25 | B33: -4.5 | C33: -70312.5 | D33: -92984.375 | E33: -163296.88
A34: 29.5 | B34: 0 | C34: 0 | D34: -92984.375 | E34: -92984.375
A35: 32 | B35: 2.5 | C35: 39062.5 | D35: -92984.375 | E35: -53921.875
A36: 35 | B36: 5.5 | C36: 85937.5 | D36: -92984.375 | E36: -7046.875 | F36: Breakeven ~
A37: 36 | B37: 6.5 | C37: 101562.5 | D37: -92984.375 | E37: 8578.125 | F37: Breakeven ~
A38: 40 | B38: 10.5 | C38: 164062.5 | D38: -92984.375 | E38: 71078.125 | F38: ✓ Profit
A39: 45 | B39: 15.5 | C39: 242187.5 | D39: -92984.375 | E39: 149203.12 | F39: ✓ Profit
A41: Entry pay-up = +29.5 ticks. Pay-up P&L = (Exit − Entry) × $312.50 × $50mm. Each tick of pay-up movement = $15,625 on $50mm notional. Breakeven exit pay-up ≈ +36 ticks (carry cost of 5.951 ticks ÷ $312.50 × $50mm = $92,984 offset). Positive total P&L requires exit pay-up > ~36 ticks.
A43: Pay-Up Outlook — Supply, Demand & Technical Dynamics
A44: Current Market Context
...

Sheet Basis Trade
A1: Basis Trade — Long FR SL4960 / Short 5Y UST (CT5)
B2: Pool Leg | C2: UST Short Leg | D2: Net
A3: Position Inputs
A4: Instrument | B4: FR SL4960 | C4: CT5 Govt (5Y UST)
A5: Direction | B5: Long | C5: Short
A6: Notional ($mm face) | B6: 50 | C6: 29.409596
A7: Price (decimal) | B7: 102.875 | C7: 99.355
A8: Coupon (%) | B8: 6 | C8: 4.125
A9: OAD / Mod Duration | B9: 2.51 | C9: 7.911
A10: DV01 per $1mm ($) | B10: 258 | C10: 439
A11: Total DV01 ($) | B11: 12911 | C11: 12911
A12: Repo / SOFR (%) | B12: 3.62 | C12: 3.66
A13: Hedge Ratio (UST $mm / Pool $mm) | C13: 0.59
A14: Monthly Carry ($ per month)
A15: Coupon Income / (Payment) | B15: 257187.5 | C15: -100443.42
A16: Repo Income / (Cost) | B16: -156884.38 | C16: 89120.707
A17: Net Leg Carry ($/month) | B17: 100303.12 | C17: -11322.713 | D17: 88980.412
A18: 3-Month P&L Summary
A19: 3-Month Carry P&L ($) | D19: 266941.24
A20: Yield Spread (pool vs 5Y UST, bps) | D20: 72.8
A21: DV01 Neutral Hedge Ratio | D21: 0.59
A23: Pool carry = (coupon − repo) × price × notional / 12. UST short carry = (repo − coupon) × price × notional / 12. Hedge ratio = pool total DV01 / UST DV01 per $1mm. Pool DV01 = OAD × price / 10,000 × $1mm. SOFR = 3.62%, repo = 3.66%. Source: Bloomberg, 6/22/2026.
A25: Basis Trade — Analysis & Risks
A26: Trade Rationale
A27: The basis trade (long FR SL4960, short 5Y UST DV01-neutral) expresses a view that MBS spreads will tighten relative to Treasuries, or at minimum hold stable, while earning positive net carry from the coupon differential. The pool's 6.0% coupon financed at SOFR (3.66%) generates substantial carry of ~$100k/month on $50mm notional. The 5Y UST short is sized to neutralize parallel rate risk (DV01 neutral at 0.59x), leaving the position exposed to MBS basis movements — the spread between MBS yields and equivalent-duration Treasuries. The 72.8 bps yield spread over the 5Y UST represents compensation for MBS-specific risks including prepayment uncertainty, negative convexity, and liquidity premium.
A28: What it Means to be Long Basis
A29: Being long basis means you profit when MBS spreads tighten (MBS outperforms Treasuries) and lose when MBS spreads widen (MBS underperforms Treasuries). MBS basis is driven by Fed balance sheet policy, bank demand, convexity hedging flows, and rate volatility. When rates are volatile, MBS negative convexity becomes more costly — investors demand wider spreads to hold MBS, which hurts a long basis position. When rates are stable and the Fed is not actively selling its MBS portfolio, basis tends to tighten as carry-seeking investors bid up MBS. The key risk to understand is that a long basis position can lose money even if rates don't move — a pure spread widening event (e.g. Fed announcing accelerated MBS runoff) would compress the position's value independent of the rate environment.
A30: Macro Tailwinds
A31: Fed rate hike in September: paradoxically, a hike can be positive for MBS basis if it signals the Fed is committed to fighting inflation and keeping rates elevated. Higher rates reduce prepay speeds, improving the carry profile of MBS relative to Treasuries and reducing negative convexity costs. Limited Fannie 6 supply constrains the float of current coupon MBS, supporting spreads as demand from banks, money managers, and hedge funds competes for scarce bonds. Stable rate volatility (low MOVE index) reduces the cost of negative convexity and supports MBS basis tightening. If the Fed maintains its current pace of MBS runoff without acceleration, the technical supply/demand balance in agency MBS remains supportive.
A32: Macro Risks
A33: Fed MBS selling acceleration: if the Fed announces an increase in the pace of MBS runoff or outright sales, supply increases sharply and MBS basis widens significantly — this is the single largest risk to a long basis position. Rate volatility spike: a sharp move in rates in either direction increases the cost of negative convexity and forces convexity hedgers to sell MBS, widening basis. This can happen even if rates ultimately end up unchanged. Bank demand reduction: if banks reduce MBS purchases due to regulatory changes or balance sheet constraints, a key buyer disappears from the market and spreads widen. Curve steepening: the 5Y UST hedge does not protect against curve twist risk — if the 5Y rallies while the long end sells off (steepening), the hedge becomes less effective and the position loses on the duration mismatch. This is particularly relevant given the Fed hike narrative which tends to flatten or invert the curve.

Sheet Coupon Stack Trade
A1: Coupon Stack Trade — Long FR SL4960 / Short FNCL 5.5 TBA
B2: Pool Leg | C2: FNCL 5.5 Short | D2: Net
A3: Position Inputs
A4: Instrument | B4: FR SL4960 | C4: FNCL 5.5 TBA
A5: Direction | B5: Long | C5: Short
A6: Notional ($mm face) | B6: 50 | C6: 37.416799
A7: Price (decimal) | B7: 102.875 | C7: 100.01562
A8: Coupon (%) | B8: 6 | C8: 5.5
A9: OAD | B9: 2.51 | C9: 3.45
A10: DV01 per $1mm ($) | B10: 258 | C10: 345
A11: Total DV01 ($) | B11: 12911 | C11: 12911
A12: Repo Rate (%) | B12: 3.66 | C12: 3.66
A13: Hedge Ratio (TBA $mm / Pool $mm) | D13: 0.75
A14: Monthly Carry ($ per month)
A15: Coupon Income / (Payment) | B15: 257187.5 | C15: -171520.46
A16: Repo (Cost) / Income | B16: -156884.38 | C16: 114139.07
A17: Net Leg Carry ($/month) | B17: 100303.12 | C17: -57381.389 | D17: 42921.736
A18: 3-Month P&L Summary
A19: 3-Month Carry P&L ($) | D19: 128765.21
A20: Coupon Spread (6.0% vs 5.5%, pct pts) | D20: 0.5
A21: Yield Spread (pool vs FNCL 5.5, bps) | D21: -22.4
A22: DV01 Neutral Hedge Ratio | D22: 0.75
A24: Pool carry = (coupon − repo) × price × notional / 12. FNCL 5.5 short carry = (repo − coupon) × price × notional / 12. Hedge ratio = pool total DV01 / FNCL 5.5 DV01 per $1mm. FNCL 5.5 OAD = 3.45, price = 100-00+ (100.015625). Repo = 3.66% (SOFR + 4bps). Source: Bloomberg, 6/22/2026.
A26: Coupon Stack Trade — Analysis & Risks
A27: Trade Rationale — Why 6s Should Outperform 5.5s
A28: The coupon stack trade (long FR SL4960 6%, short FNCL 5.5 TBA DV01-neutral) is a relative value bet that the 6% coupon outperforms the 5.5% coupon on a spread basis. The core argument is that 6s are the current coupon — most new origination is pricing at 6% WAC, meaning 6s have the most favorable supply/demand dynamics of any coupon in the stack. Current coupon MBS typically commands the tightest OAS because it is the most liquid, most actively traded, and most sought after by investors who want duration-adjusted carry. 5.5s by contrast are slightly off-the-run — they were the current coupon when rates were lower and now carry slightly elevated prepay risk as borrowers with 5.5% mortgages are closer to refinancing if rates decline. This makes 5.5s more negatively convex at current rate levels relative to 6s, which should cause 6s to outperform in a spread tightening environment.
A29: Supply Dynamics Favor 6s
A30: Limited supply of Fannie 6s is a structural tailwind for the long leg. With origination volumes suppressed by elevated rates, new FNCL 6 pools are not coming to market at a pace that satisfies investor demand. The existing float of 6% MBS is being absorbed by carry-seeking buyers including hedge funds, money managers, and some bank portfolios, keeping OAS tight and prices supported. Meanwhile the 5.5 coupon has a larger existing float from prior origination vintages and faces more supply risk if rates rally and refinancing activity picks up for borrowers with slightly higher mortgage rates. Short the 5.5 TBA therefore positions you against the coupon most vulnerable to supply and prepay acceleration.
A31: Macro Tailwinds
A32: Fed rate hike in September: a hike directly supports the 6% coupon by keeping mortgage rates elevated and origination volumes low, maintaining supply scarcity. It also increases prepay risk for 5.5s relative to 6s at the margin — borrowers with 5.5% mortgages are closer to the refinancing threshold than 6% borrowers, so any rate decline (even partial) hits 5.5s harder. This convexity differential should cause 6s to outperform 5.5s in a rates-stable or rates-higher environment. Continued hedge fund demand in current coupon: institutional flows into 6% MBS provide a technical bid that is absent in the 5.5 coupon, supporting the spread compression thesis between the two coupons.
A33: Macro Risks
A34: Rates rally: if rates decline meaningfully, 6% borrowers move closer to refinancing and prepay risk in 6s increases sharply. This would compress the pay-up advantage of spec pools in the 6% stack and could cause 6s to underperform 5.5s as the market reprices prepay risk. In a strong rally scenario, 5.5s could actually outperform 6s because their borrowers are already partially refinancing — a rates decline accelerates existing 5.5 prepays and shortens duration, making 5.5 TBA relatively more valuable in a rally. Roll divergence: if the FNCL 5.5 TBA roll richness diverges significantly from the 6% roll, the hedge cost changes in a way that is not captured in this carry calculation. Coupon drift: as rates move, the current coupon designation shifts — if 6s become off-the-run and 6.5s become current coupon, demand rotates away from 6s and the relative value thesis breaks down. OAS convergence: if the spread between 6% and 5.5% OAS compresses due to technical factors rather than fundamentals, the position loses mark-to-market even if carry remains positive.

Sheet Assumptions
A1: CARRY ANALYSIS – ASSUMPTIONS
A2: TRADE SELECTION
A3: Selected Pool | B3: FR SL4960 | C3: FICO story pool – FR; chosen on RV
A4: Ticker | B4: FR SL4960 | C4: Bloomberg: FR SL4960 Mtge
A5: Coupon (%) | B5: 6 | C5: Source: Bloomberg DES 6/22/2026
A6: Pool Price (clean, 32nds-decimal) | B6: 102.875 | C6: 102-28 = 102 + 28/32
A7: Pay-Up over TBA (ticks, 1/32nds) | B7: 29.5 | C7: +29+ means 29 and 1/2 tick = 29.5/32nds; Source: desk
A9: TBA ROLL (OBSERVED – FNCL 6 7/26)
A10: Jul-Aug Drop (ticks 1/32nd) | B10: 3.936 | C10: Observed spec drop at 102-23 (TBA+payup), 17.3 CPR, 3.7% IFR, 7/13→8/13; Source: Bloomberg RA 6/22/2026
A11: Aug-Sep Drop (ticks 1/32nd) | B11: 4.132 | C11: Observed spec drop at 102-23 (TBA+payup), 17.3 CPR, 3.7% IFR, 8/13→9/14; Source: Bloomberg RA 6/22/2026
A12: Sep-Oct Drop (by CPR) | B12: See CPR table below (rows 50-55) | C12: Bloomberg RA FNCL 6, 9/14→10/13, imm. price 102-23, IFR 3.95%
A14: IMPLIED FINANCING RATE (B/E FIN RATE)
A15: Jul-Aug IFR (%) | B15: 3.7 | C15: Source: Bloomberg RA screen 6/22/2026
A16: Aug-Sep IFR (%) | B16: 3.7 | C16: Same as Jul-Aug; desk guidance
A17: Sep-Oct IFR (%) | B17: 3.95 | C17: Priced-in Fed hike; desk guidance
A19: PREPAYMENT SCENARIOS (CPR)
A20: CPR Min (%) | B20: 5 | C20: Lower bound of scenario range
A21: CPR Max (%) | B21: 25 | C21: Upper bound of scenario range
A22: CPR Step | B22: 5 | C22: Increment
A23: Base-Case CPR (%) | B23: 17.3 | C23: FR SL4960 1M CPR Jun-26; Source: Bloomberg DES
A24: 3M CPR (%) | B24: 19.4 | C24: FR SL4960 3M CPR Jun-26; Source: Bloomberg DES 6/22/2026
A26: POOL CHARACTERISTICS (FR SL4960)
A27: WAC (%) | B27: 6.974 | C27: Source: Bloomberg DES 6/22/2026
A28: WAM (months) | B28: 325 | C28: Source: Bloomberg DES
A29: WALA (months) | B29: 30 | C29: Source: Bloomberg DES
A30: Avg FICO | B30: 676 | C30: Source: Bloomberg DES; CL FICO story
A31: Avg LTV | B31: 80 | C31: Source: Bloomberg DES
A32: # Loans | B32: 2841 | C32: Source: Bloomberg DES
A33: Balance ($mm) | B33: 110.28 | C33: Current UPB; Source: Bloomberg DES
A34: Vintage | B34: FNCL 6 2023 | C34: Source: Bloomberg DES
A36: Jul-Aug POOL CARRY by CPR (RA, imm=102-23, IFR=3.7%) | B36: Drop (ticks) | C36: Source: Bloomberg RA FNCL 6 7/26, 7/13→8/13, 6/22/2026
A37: 5% CPR | B37: 5.009
A38: 10% CPR | B38: 4.592
A39: 15% CPR | B39: 4.15
A40: 17% CPR | B40: 3.965
A41: 20% CPR | B41: 3.679
A42: 25% CPR | B42: 3.175
A43: Aug-Sep POOL CARRY by CPR (RA, imm=102-23, IFR=3.7%) | B43: Drop (ticks) | C43: Source: Bloomberg RA FNCL 6 7/26, 8/13→9/14, 6/22/2026
A44: 5% CPR | B44: 5.204
A45: 10% CPR | B45: 4.788
...

Sheet TBA Roll Table
A1: TBA ROLL CARRY TABLE (in ticks, 1/32nd per $1mm face)
A2: TBA Roll Cost = negative of the generic TBA drop (RA at TBA price, no pay-up). Jul-Aug: −8.000 ticks. Aug-Sep: −5.750 ticks (CPR-invariant for near months). Sep-Oct: CPR-specific drops from Bloomberg RA at generic price (run separately).
A3: Mechanics: Rolling a TBA short = sell near, buy far. You receive the drop when you roll from near to far. For SPECIAL pools the TBA trades rich, so the special drop is HIGHER than the generic roll – this is a COST to the spec pool long position. Net TBA roll carry = −Drop (the short TBA roll is a negative carry item).
A4: CPR Scenario | B4: Jul-Aug | C4: Aug-Sep | D4: Sep-Oct
A5: 5% CPR | B5: =-Assumptions!$B$58 -> -8 | C5: =-Assumptions!$B$59 -> -5.75 | D5: =-Assumptions!$B$62 -> -4.732
A6: 10% CPR | B6: =-Assumptions!$B$58 -> -8 | C6: =-Assumptions!$B$59 -> -5.75 | D6: =-Assumptions!$B$63 -> -4.447
A7: 15% CPR | B7: =-Assumptions!$B$58 -> -8 | C7: =-Assumptions!$B$59 -> -5.75 | D7: =-Assumptions!$B$64 -> -4.145
A8: 17% CPR | B8: =-Assumptions!$B$58 -> -8 | C8: =-Assumptions!$B$59 -> -5.75 | D8: =-Assumptions!$B$65 -> -4.018
A9: 20% CPR | B9: =-Assumptions!$B$58 -> -8 | C9: =-Assumptions!$B$59 -> -5.75 | D9: =-Assumptions!$B$66 -> -3.823
A10: 25% CPR | B10: =-Assumptions!$B$58 -> -8 | C10: =-Assumptions!$B$59 -> -5.75 | D10: =-Assumptions!$B$67 -> -3.478
A11: BASE CASE (17% CPR ≈ 1M CPR of FR SL4960)

Sheet Pool Carry Table
A1: POOL CARRY TABLE (in ticks, 1/32nd per $1mm face)
A2: Pool Carry = Bloomberg RA forward drop at adjusted imm. price (TBA + 29.5 tick pay-up = 102-23). Jul-Aug and Aug-Sep are flat across CPR rows (near-term dates lock in observed speed at 17.3 CPR). Sep-Oct is CPR-specific from Bloomberg RA. Jul-Aug observed drop: 3.936. Aug-Sep observed drop: 4.132.
A3: Formula: Pool Carry (ticks) = TBA Drop (ticks) − [ Pay-Up (ticks) × IFR% / 12 ] where IFR is the B/E financing rate for that month from Bloomberg RA. Sep-Oct: Pool Carry is SET EQUAL to Pool Carry (assumption per desk) because Sep-Oct TBA drop is not yet tradeable; it equals the carry earned.
A4: CPR Scenario | B4: Jul-Aug | C4: Aug-Sep | D4: Sep-Oct
A5: 5% CPR | B5: =Assumptions!$B$10 -> 3.936 | C5: =Assumptions!$B$11 -> 4.132 | D5: =Assumptions!$B$51 -> 4.483
A6: 10% CPR | B6: =Assumptions!$B$10 -> 3.936 | C6: =Assumptions!$B$11 -> 4.132 | D6: =Assumptions!$B$52 -> 4.064
A7: 15% CPR | B7: =Assumptions!$B$10 -> 3.936 | C7: =Assumptions!$B$11 -> 4.132 | D7: =Assumptions!$B$53 -> 3.619
A8: 17% CPR | B8: =Assumptions!$B$10 -> 3.936 | C8: =Assumptions!$B$11 -> 4.132 | D8: =Assumptions!$B$54 -> 3.433
A9: 20% CPR | B9: =Assumptions!$B$10 -> 3.936 | C9: =Assumptions!$B$11 -> 4.132 | D9: =Assumptions!$B$55 -> 3.145
A10: 25% CPR | B10: =Assumptions!$B$10 -> 3.936 | C10: =Assumptions!$B$11 -> 4.132 | D10: =Assumptions!$B$56 -> 2.637
A11: BASE CASE (17% CPR ≈ 1M CPR of FR SL4960)

Sheet Net Carry Summary
A1: NET CARRY SUMMARY (ticks, 1/32nd) – Spec Pool Long vs TBA Short Hedge
A2: Position: LONG FR SL4960 spec pool + SHORT FNCL 6 TBA (hedge). The TBA roll is a COST (negative) because special pools command a higher drop. The Pool earns carry from its coupon relative to its financing cost (the drop). Net Carry = Pool Carry – TBA Roll Cost. Positive = carry-positive position.
A3: Component | B3: Jul-Aug | C3: Aug-Sep | D3: Sep-Oct | E3: 3-Month Total
A4: BASE CASE (17% CPR ≈ FR SL4960 1M CPR)
A5: Pool Carry (ticks) | B5: 3.936 | C5: 4.246 | D5: 4.064 | E5: 12.246
A6: TBA Roll Cost (ticks, negative) | B6: -8 | C6: -5.75 | D6: -4.447 | E6: -18.197
A7: NET CARRY (Pool + TBA Roll Cost) | B7: -4.064 | C7: -1.504 | D7: -0.383 | E7: -5.951
A9: CPR SENSITIVITY – NET CARRY (ticks)
A10: CPR Scenario | B10: Jul-Aug | C10: Aug-Sep | D10: Sep-Oct | E10: 3-Month Total
A11: 5% CPR | B11: -4.064 | C11: -1.504 | D11: -0.249 | E11: -5.817
A12: 10% CPR | B12: -4.064 | C12: -1.504 | D12: -0.383 | E12: -5.951
A13: 15% CPR | B13: -4.064 | C13: -1.504 | D13: -0.526 | E13: -6.094
A14: 17% CPR | B14: -4.064 | C14: -1.504 | D14: -0.585 | E14: -6.153
A15: 20% CPR | B15: -4.064 | C15: -1.504 | D15: -0.678 | E15: -6.246
A16: 25% CPR | B16: -4.064 | C16: -1.504 | D16: -0.841 | E16: -6.409
